Traceback (most recent call last):
  File "/home/puneet/venv/lib/python3.10/site-packages/jupyter_cache/executors/utils.py", line 58, in single_nb_execution
    executenb(
  File "/home/puneet/venv/lib/python3.10/site-packages/nbclient/client.py", line 1314, in execute
    return NotebookClient(nb=nb, resources=resources, km=km, **kwargs).execute()
  File "/home/puneet/venv/lib/python3.10/site-packages/jupyter_core/utils/__init__.py", line 165, in wrapped
    return loop.run_until_complete(inner)
  File "/usr/lib/python3.10/asyncio/base_events.py", line 649, in run_until_complete
    return future.result()
  File "/home/puneet/venv/lib/python3.10/site-packages/nbclient/client.py", line 709, in async_execute
    await self.async_execute_cell(
  File "/home/puneet/venv/lib/python3.10/site-packages/nbclient/client.py", line 1062, in async_execute_cell
    await self._check_raise_for_error(cell, cell_index, exec_reply)
  File "/home/puneet/venv/lib/python3.10/site-packages/nbclient/client.py", line 918, in _check_raise_for_error
    raise CellExecutionError.from_cell_and_msg(cell, exec_reply_content)
nbclient.exceptions.CellExecutionError: An error occurred while executing the following cell:
------------------
llm = ChatTogether(
    model="mistralai/Mistral-7B-Instruct-v0.3",
)
------------------


[0;31m---------------------------------------------------------------------------[0m
[0;31mNameError[0m                                 Traceback (most recent call last)
Cell [0;32mIn[4], line 1[0m
[0;32m----> 1[0m llm [38;5;241m=[39m [43mChatTogether[49m(
[1;32m      2[0m     model[38;5;241m=[39m[38;5;124m"[39m[38;5;124mmistralai/Mistral-7B-Instruct-v0.3[39m[38;5;124m"[39m,
[1;32m      3[0m )

[0;31mNameError[0m: name 'ChatTogether' is not defined

